[2023-08-31T02:26:12.191+0000] {taskinstance.py:1159} INFO - Dependencies all met for dep_context=non-requeueable deps ti=<TaskInstance: vnstock-pipeline-1M.Vm_pub_pubsub_1M scheduled__2023-08-31T01:45:00+00:00 [queued]>
[2023-08-31T02:26:12.196+0000] {taskinstance.py:1159} INFO - Dependencies all met for dep_context=requeueable deps ti=<TaskInstance: vnstock-pipeline-1M.Vm_pub_pubsub_1M scheduled__2023-08-31T01:45:00+00:00 [queued]>
[2023-08-31T02:26:12.196+0000] {taskinstance.py:1361} INFO - Starting attempt 1 of 4
[2023-08-31T02:26:12.210+0000] {taskinstance.py:1382} INFO - Executing <Task(PythonOperator): Vm_pub_pubsub_1M> on 2023-08-31 01:45:00+00:00
[2023-08-31T02:26:12.215+0000] {clientserver.py:543} INFO - Closing down clientserver connection
[2023-08-31T02:26:12.215+0000] {standard_task_runner.py:57} INFO - Started process 471277 to run task
[2023-08-31T02:26:12.219+0000] {clientserver.py:538} INFO - Error while receiving.
Traceback (most recent call last):
  File "/home/nguyentuanduong7/.local/lib/python3.8/site-packages/py4j/clientserver.py", line 516, in send_command
    raise Py4JNetworkError("Answer from Java side is empty")
py4j.protocol.Py4JNetworkError: Answer from Java side is empty
[2023-08-31T02:26:12.220+0000] {clientserver.py:543} INFO - Closing down clientserver connection
[2023-08-31T02:26:12.221+0000] {java_gateway.py:1055} ERROR - Exception while sending command.
Traceback (most recent call last):
  File "/home/nguyentuanduong7/.local/lib/python3.8/site-packages/py4j/clientserver.py", line 516, in send_command
    raise Py4JNetworkError("Answer from Java side is empty")
py4j.protocol.Py4JNetworkError: Answer from Java side is empty

During handling of the above exception, another exception occurred:

Traceback (most recent call last):
  File "/home/nguyentuanduong7/.local/lib/python3.8/site-packages/py4j/java_gateway.py", line 1038, in send_command
    response = connection.send_command(command)
  File "/home/nguyentuanduong7/.local/lib/python3.8/site-packages/py4j/clientserver.py", line 539, in send_command
    raise Py4JNetworkError(
py4j.protocol.Py4JNetworkError: Error while sending or receiving
[2023-08-31T02:26:12.221+0000] {clientserver.py:543} INFO - Closing down clientserver connection
[2023-08-31T02:26:12.226+0000] {standard_task_runner.py:84} INFO - Running: ['airflow', 'tasks', 'run', 'vnstock-pipeline-1M', 'Vm_pub_pubsub_1M', 'scheduled__2023-08-31T01:45:00+00:00', '--job-id', '404', '--raw', '--subdir', 'DAGS_FOLDER/main.py', '--cfg-path', '/tmp/tmpwiy5uzqz']
[2023-08-31T02:26:12.227+0000] {standard_task_runner.py:85} INFO - Job 404: Subtask Vm_pub_pubsub_1M
[2023-08-31T02:26:12.270+0000] {task_command.py:415} INFO - Running <TaskInstance: vnstock-pipeline-1M.Vm_pub_pubsub_1M scheduled__2023-08-31T01:45:00+00:00 [running]> on host vnstock-pipeline-vm.us-central1-c.c.vnstock-pipeline.internal
[2023-08-31T02:26:12.332+0000] {taskinstance.py:1660} INFO - Exporting env vars: AIRFLOW_CTX_DAG_EMAIL='nguyentuanduong555@gmail.com' AIRFLOW_CTX_DAG_OWNER='Duong_' AIRFLOW_CTX_DAG_ID='vnstock-pipeline-1M' AIRFLOW_CTX_TASK_ID='Vm_pub_pubsub_1M' AIRFLOW_CTX_EXECUTION_DATE='2023-08-31T01:45:00+00:00' AIRFLOW_CTX_TRY_NUMBER='1' AIRFLOW_CTX_DAG_RUN_ID='scheduled__2023-08-31T01:45:00+00:00'
[2023-08-31T02:26:12.336+0000] {python.py:194} INFO - Done. Returned value was: None
[2023-08-31T02:26:12.339+0000] {taskinstance.py:1400} INFO - Marking task as SUCCESS. dag_id=vnstock-pipeline-1M, task_id=Vm_pub_pubsub_1M, execution_date=20230831T014500, start_date=20230831T022612, end_date=20230831T022612
[2023-08-31T02:26:12.354+0000] {local_task_job_runner.py:228} INFO - Task exited with return code 0
[2023-08-31T02:26:12.365+0000] {taskinstance.py:2784} INFO - 0 downstream tasks scheduled from follow-on schedule check
