[2023-08-30T16:47:22.953+0000] {taskinstance.py:1159} INFO - Dependencies all met for dep_context=non-requeueable deps ti=<TaskInstance: vnstock-pipeline-1D.simulate_failure_task manual__2023-08-30T16:47:03.364305+00:00 [queued]>
[2023-08-30T16:47:22.958+0000] {taskinstance.py:1159} INFO - Dependencies all met for dep_context=requeueable deps ti=<TaskInstance: vnstock-pipeline-1D.simulate_failure_task manual__2023-08-30T16:47:03.364305+00:00 [queued]>
[2023-08-30T16:47:22.959+0000] {taskinstance.py:1361} INFO - Starting attempt 1 of 4
[2023-08-30T16:47:22.975+0000] {taskinstance.py:1382} INFO - Executing <Task(PythonOperator): simulate_failure_task> on 2023-08-30 16:47:03.364305+00:00
[2023-08-30T16:47:22.979+0000] {standard_task_runner.py:57} INFO - Started process 451212 to run task
[2023-08-30T16:47:22.987+0000] {clientserver.py:543} INFO - Closing down clientserver connection
[2023-08-30T16:47:22.993+0000] {standard_task_runner.py:84} INFO - Running: ['airflow', 'tasks', 'run', 'vnstock-pipeline-1D', 'simulate_failure_task', 'manual__2023-08-30T16:47:03.364305+00:00', '--job-id', '376', '--raw', '--subdir', 'DAGS_FOLDER/main.py', '--cfg-path', '/tmp/tmpabfe1tx8']
[2023-08-30T16:47:22.993+0000] {standard_task_runner.py:85} INFO - Job 376: Subtask simulate_failure_task
[2023-08-30T16:47:23.032+0000] {task_command.py:415} INFO - Running <TaskInstance: vnstock-pipeline-1D.simulate_failure_task manual__2023-08-30T16:47:03.364305+00:00 [running]> on host vnstock-pipeline-vm.us-central1-c.c.vnstock-pipeline.internal
[2023-08-30T16:47:23.085+0000] {taskinstance.py:1660} INFO - Exporting env vars: AIRFLOW_CTX_DAG_EMAIL='nguyentuanduong555@gmail.com' AIRFLOW_CTX_DAG_OWNER='Duong_' AIRFLOW_CTX_DAG_ID='vnstock-pipeline-1D' AIRFLOW_CTX_TASK_ID='simulate_failure_task' AIRFLOW_CTX_EXECUTION_DATE='2023-08-30T16:47:03.364305+00:00' AIRFLOW_CTX_TRY_NUMBER='1' AIRFLOW_CTX_DAG_RUN_ID='manual__2023-08-30T16:47:03.364305+00:00'
[2023-08-30T16:47:23.087+0000] {taskinstance.py:1943} ERROR - Task failed with exception
Traceback (most recent call last):
  File "/usr/local/lib/python3.8/dist-packages/airflow/operators/python.py", line 192, in execute
    return_value = self.execute_callable()
  File "/usr/local/lib/python3.8/dist-packages/airflow/operators/python.py", line 209, in execute_callable
    return self.python_callable(*self.op_args, **self.op_kwargs)
  File "/home/nguyentuanduong7/airflow/src/dags/main.py", line 27, in simulate_failure
    raise Exception("This task has failed intentionally.")
Exception: This task has failed intentionally.
[2023-08-30T16:47:23.092+0000] {taskinstance.py:1400} INFO - Marking task as UP_FOR_RETRY. dag_id=vnstock-pipeline-1D, task_id=simulate_failure_task, execution_date=20230830T164703, start_date=20230830T164722, end_date=20230830T164723
[2023-08-30T16:47:23.107+0000] {logging_mixin.py:151} WARNING - /usr/local/lib/python3.8/dist-packages/airflow/utils/email.py:154 RemovedInAirflow3Warning: Fetching SMTP credentials from configuration variables will be deprecated in a future release. Please set credentials using a connection instead.
[2023-08-30T16:47:23.108+0000] {email.py:270} INFO - Email alerting: attempt 1
[2023-08-30T16:47:23.359+0000] {email.py:282} INFO - Sent an alert email to ['nguyentuanduong555@gmail.com']
[2023-08-30T16:47:24.240+0000] {standard_task_runner.py:104} ERROR - Failed to execute job 376 for task simulate_failure_task (This task has failed intentionally.; 451212)
[2023-08-30T16:47:24.278+0000] {local_task_job_runner.py:228} INFO - Task exited with return code 1
[2023-08-30T16:47:24.295+0000] {taskinstance.py:2784} INFO - 0 downstream tasks scheduled from follow-on schedule check
