[2023-08-23T12:03:53.538+0000] {taskinstance.py:1159} INFO - Dependencies all met for dep_context=non-requeueable deps ti=<TaskInstance: vnstock-pipeline.Vm_pubsub_3M manual__2023-08-23T11:01:03.194505+00:00 [queued]>
[2023-08-23T12:03:53.543+0000] {taskinstance.py:1159} INFO - Dependencies all met for dep_context=requeueable deps ti=<TaskInstance: vnstock-pipeline.Vm_pubsub_3M manual__2023-08-23T11:01:03.194505+00:00 [queued]>
[2023-08-23T12:03:53.544+0000] {taskinstance.py:1361} INFO - Starting attempt 7 of 4
[2023-08-23T12:03:53.556+0000] {taskinstance.py:1382} INFO - Executing <Task(PythonOperator): Vm_pubsub_3M> on 2023-08-23 11:01:03.194505+00:00
[2023-08-23T12:03:53.560+0000] {standard_task_runner.py:57} INFO - Started process 16449 to run task
[2023-08-23T12:03:53.560+0000] {clientserver.py:543} INFO - Closing down clientserver connection
[2023-08-23T12:03:53.568+0000] {standard_task_runner.py:84} INFO - Running: ['airflow', 'tasks', 'run', 'vnstock-pipeline', 'Vm_pubsub_3M', 'manual__2023-08-23T11:01:03.194505+00:00', '--job-id', '34', '--raw', '--subdir', 'DAGS_FOLDER/main.py', '--cfg-path', '/tmp/tmpjc0emoni']
[2023-08-23T12:03:53.568+0000] {standard_task_runner.py:85} INFO - Job 34: Subtask Vm_pubsub_3M
[2023-08-23T12:03:53.605+0000] {task_command.py:415} INFO - Running <TaskInstance: vnstock-pipeline.Vm_pubsub_3M manual__2023-08-23T11:01:03.194505+00:00 [running]> on host vnstock-pipeline-vm.us-central1-c.c.vnstock-pipeline.internal
[2023-08-23T12:03:53.654+0000] {taskinstance.py:1660} INFO - Exporting env vars: AIRFLOW_CTX_DAG_EMAIL='nguyentuanduong555@gmail.com' AIRFLOW_CTX_DAG_OWNER='Duong' AIRFLOW_CTX_DAG_ID='vnstock-pipeline' AIRFLOW_CTX_TASK_ID='Vm_pubsub_3M' AIRFLOW_CTX_EXECUTION_DATE='2023-08-23T11:01:03.194505+00:00' AIRFLOW_CTX_TRY_NUMBER='7' AIRFLOW_CTX_DAG_RUN_ID='manual__2023-08-23T11:01:03.194505+00:00'
[2023-08-23T12:03:53.743+0000] {clientserver.py:505} INFO - Error while sending or receiving.
Traceback (most recent call last):
  File "/home/nguyentuanduong7/.local/lib/python3.8/site-packages/py4j/clientserver.py", line 503, in send_command
    self.socket.sendall(command.encode("utf-8"))
ConnectionResetError: [Errno 104] Connection reset by peer
[2023-08-23T12:03:53.745+0000] {clientserver.py:543} INFO - Closing down clientserver connection
[2023-08-23T12:03:53.745+0000] {java_gateway.py:1052} INFO - Exception while sending command.
Traceback (most recent call last):
  File "/home/nguyentuanduong7/.local/lib/python3.8/site-packages/py4j/clientserver.py", line 503, in send_command
    self.socket.sendall(command.encode("utf-8"))
ConnectionResetError: [Errno 104] Connection reset by peer

During handling of the above exception, another exception occurred:

Traceback (most recent call last):
  File "/home/nguyentuanduong7/.local/lib/python3.8/site-packages/py4j/java_gateway.py", line 1038, in send_command
    response = connection.send_command(command)
  File "/home/nguyentuanduong7/.local/lib/python3.8/site-packages/py4j/clientserver.py", line 506, in send_command
    raise Py4JNetworkError(
py4j.protocol.Py4JNetworkError: Error while sending
[2023-08-23T12:03:53.755+0000] {clientserver.py:543} INFO - Closing down clientserver connection
[2023-08-23T12:03:58.651+0000] {logging_mixin.py:151} INFO - root
 |-- Time: timestamp (nullable = true)
 |-- Ticker: string (nullable = true)
 |-- Close: double (nullable = true)
 |-- Percentage_Change: double (nullable = true)
[2023-08-23T12:04:28.854+0000] {local_task_job_runner.py:294} WARNING - State of this instance has been externally set to restarting. Terminating instance.
[2023-08-23T12:04:28.857+0000] {process_utils.py:131} INFO - Sending Signals.SIGTERM to group 16449. PIDs of all processes in the group: [16449]
[2023-08-23T12:04:28.858+0000] {process_utils.py:86} INFO - Sending the signal Signals.SIGTERM to group 16449
[2023-08-23T12:04:28.858+0000] {taskinstance.py:1632} ERROR - Received SIGTERM. Terminating subprocesses.
[2023-08-23T12:04:28.862+0000] {taskinstance.py:1943} ERROR - Task failed with exception
Traceback (most recent call last):
  File "/usr/local/lib/python3.8/dist-packages/airflow/operators/python.py", line 192, in execute
    return_value = self.execute_callable()
  File "/usr/local/lib/python3.8/dist-packages/airflow/operators/python.py", line 209, in execute_callable
    return self.python_callable(*self.op_args, **self.op_kwargs)
  File "/home/nguyentuanduong7/airflow/src/pluggin/vm_pubsub_bq.py", line 101, in vm_pubsub_3M
    spark.stop()
  File "/home/nguyentuanduong7/.local/lib/python3.8/site-packages/pyspark/sql/session.py", line 1599, in stop
    self._sc.stop()
  File "/home/nguyentuanduong7/.local/lib/python3.8/site-packages/pyspark/context.py", line 663, in stop
    self._accumulatorServer.shutdown()
  File "/home/nguyentuanduong7/.local/lib/python3.8/site-packages/pyspark/accumulators.py", line 302, in shutdown
    SocketServer.TCPServer.shutdown(self)
  File "/usr/lib/python3.8/socketserver.py", line 252, in shutdown
    self.__is_shut_down.wait()
  File "/usr/lib/python3.8/threading.py", line 558, in wait
    signaled = self._cond.wait(timeout)
  File "/usr/lib/python3.8/threading.py", line 302, in wait
    waiter.acquire()
  File "/usr/local/lib/python3.8/dist-packages/airflow/models/taskinstance.py", line 1634, in signal_handler
    raise AirflowException("Task received SIGTERM signal")
airflow.exceptions.AirflowException: Task received SIGTERM signal
[2023-08-23T12:04:28.868+0000] {taskinstance.py:1400} INFO - Marking task as UP_FOR_RETRY. dag_id=vnstock-pipeline, task_id=Vm_pubsub_3M, execution_date=20230823T110103, start_date=20230823T120353, end_date=20230823T120428
[2023-08-23T12:04:28.885+0000] {logging_mixin.py:151} WARNING - /usr/local/lib/python3.8/dist-packages/airflow/utils/email.py:154 RemovedInAirflow3Warning: Fetching SMTP credentials from configuration variables will be deprecated in a future release. Please set credentials using a connection instead.
[2023-08-23T12:04:28.885+0000] {configuration.py:1064} WARNING - section/key [smtp/smtp_user] not found in config
[2023-08-23T12:04:28.885+0000] {email.py:270} INFO - Email alerting: attempt 1
[2023-08-23T12:04:28.888+0000] {configuration.py:1064} WARNING - section/key [smtp/smtp_user] not found in config
[2023-08-23T12:04:28.888+0000] {email.py:270} INFO - Email alerting: attempt 1
[2023-08-23T12:04:28.888+0000] {taskinstance.py:2013} ERROR - Failed to send email to: ['nguyentuanduong555@gmail.com']
Traceback (most recent call last):
  File "/usr/local/lib/python3.8/dist-packages/airflow/models/taskinstance.py", line 1518, in _run_raw_task
    self._execute_task_with_callbacks(context, test_mode, session=session)
  File "/usr/local/lib/python3.8/dist-packages/airflow/models/taskinstance.py", line 1679, in _execute_task_with_callbacks
    result = self._execute_task(context, task_orig)
  File "/usr/local/lib/python3.8/dist-packages/airflow/models/taskinstance.py", line 1750, in _execute_task
    result = execute_callable(context=context)
  File "/usr/local/lib/python3.8/dist-packages/airflow/operators/python.py", line 192, in execute
    return_value = self.execute_callable()
  File "/usr/local/lib/python3.8/dist-packages/airflow/operators/python.py", line 209, in execute_callable
    return self.python_callable(*self.op_args, **self.op_kwargs)
  File "/home/nguyentuanduong7/airflow/src/pluggin/vm_pubsub_bq.py", line 101, in vm_pubsub_3M
    spark.stop()
  File "/home/nguyentuanduong7/.local/lib/python3.8/site-packages/pyspark/sql/session.py", line 1599, in stop
    self._sc.stop()
  File "/home/nguyentuanduong7/.local/lib/python3.8/site-packages/pyspark/context.py", line 663, in stop
    self._accumulatorServer.shutdown()
  File "/home/nguyentuanduong7/.local/lib/python3.8/site-packages/pyspark/accumulators.py", line 302, in shutdown
    SocketServer.TCPServer.shutdown(self)
  File "/usr/lib/python3.8/socketserver.py", line 252, in shutdown
    self.__is_shut_down.wait()
  File "/usr/lib/python3.8/threading.py", line 558, in wait
    signaled = self._cond.wait(timeout)
  File "/usr/lib/python3.8/threading.py", line 302, in wait
    waiter.acquire()
  File "/usr/local/lib/python3.8/dist-packages/airflow/models/taskinstance.py", line 1634, in signal_handler
    raise AirflowException("Task received SIGTERM signal")
airflow.exceptions.AirflowException: Task received SIGTERM signal

During handling of the above exception, another exception occurred:

Traceback (most recent call last):
  File "/usr/local/lib/python3.8/dist-packages/airflow/models/taskinstance.py", line 2426, in email_alert
    send_email(task.email, subject, html_content)
  File "/usr/local/lib/python3.8/dist-packages/airflow/utils/email.py", line 80, in send_email
    return backend(
  File "/usr/local/lib/python3.8/dist-packages/airflow/utils/email.py", line 154, in send_email_smtp
    send_mime_email(e_from=mail_from, e_to=recipients, mime_msg=msg, conn_id=conn_id, dryrun=dryrun)
  File "/usr/local/lib/python3.8/dist-packages/airflow/utils/email.py", line 272, in send_mime_email
    smtp_conn = _get_smtp_connection(smtp_host, smtp_port, smtp_timeout, smtp_ssl)
  File "/usr/local/lib/python3.8/dist-packages/airflow/utils/email.py", line 317, in _get_smtp_connection
    return smtplib.SMTP(host=host, port=port, timeout=timeout)
  File "/usr/lib/python3.8/smtplib.py", line 255, in __init__
    (code, msg) = self.connect(host, port)
  File "/usr/lib/python3.8/smtplib.py", line 339, in connect
    self.sock = self._get_socket(host, port, self.timeout)
  File "/usr/lib/python3.8/smtplib.py", line 310, in _get_socket
    return socket.create_connection((host, port), timeout,
  File "/usr/lib/python3.8/socket.py", line 808, in create_connection
    raise err
  File "/usr/lib/python3.8/socket.py", line 796, in create_connection
    sock.connect(sa)
ConnectionRefusedError: [Errno 111] Connection refused

During handling of the above exception, another exception occurred:

Traceback (most recent call last):
  File "/usr/local/lib/python3.8/dist-packages/airflow/models/taskinstance.py", line 2011, in handle_failure
    self.email_alert(error, task)
  File "/usr/local/lib/python3.8/dist-packages/airflow/models/taskinstance.py", line 2428, in email_alert
    send_email(task.email, subject, html_content_err)
  File "/usr/local/lib/python3.8/dist-packages/airflow/utils/email.py", line 80, in send_email
    return backend(
  File "/usr/local/lib/python3.8/dist-packages/airflow/utils/email.py", line 154, in send_email_smtp
    send_mime_email(e_from=mail_from, e_to=recipients, mime_msg=msg, conn_id=conn_id, dryrun=dryrun)
  File "/usr/local/lib/python3.8/dist-packages/airflow/utils/email.py", line 272, in send_mime_email
    smtp_conn = _get_smtp_connection(smtp_host, smtp_port, smtp_timeout, smtp_ssl)
  File "/usr/local/lib/python3.8/dist-packages/airflow/utils/email.py", line 317, in _get_smtp_connection
    return smtplib.SMTP(host=host, port=port, timeout=timeout)
  File "/usr/lib/python3.8/smtplib.py", line 255, in __init__
    (code, msg) = self.connect(host, port)
  File "/usr/lib/python3.8/smtplib.py", line 339, in connect
    self.sock = self._get_socket(host, port, self.timeout)
  File "/usr/lib/python3.8/smtplib.py", line 310, in _get_socket
    return socket.create_connection((host, port), timeout,
  File "/usr/lib/python3.8/socket.py", line 808, in create_connection
    raise err
  File "/usr/lib/python3.8/socket.py", line 796, in create_connection
    sock.connect(sa)
ConnectionRefusedError: [Errno 111] Connection refused
[2023-08-23T12:04:28.898+0000] {standard_task_runner.py:104} ERROR - Failed to execute job 34 for task Vm_pubsub_3M (Task received SIGTERM signal; 16449)
[2023-08-23T12:04:28.910+0000] {process_utils.py:79} INFO - Process psutil.Process(pid=16449, status='terminated', exitcode=1, started='12:03:52') (16449) terminated with exit code 1
